#VRML_SIM R2022a utf8
WorldInfo {
}
Viewpoint {
  orientation -0.5773502691896258 0.5773502691896258 0.5773502691896258 2.0944
  position 0.4999998414659171 -3.9264315438022436e-16 2.613141581697173
}
TexturedBackground {
}
TexturedBackgroundLight {
}
RectangleArena {
}
Robot {
  translation 0 0 0.005
  children [
    SliderJoint {
      jointParameters JointParameters {
      }
      device [
        PositionSensor {
        }
        LinearMotor {
          name "L1"
        }
      ]
      endPoint Solid {
        translation 0 0 0.125
        children [
          HingeJoint {
            device [
              PositionSensor {
              }
              RotationalMotor {
                name "R1"
              }
            ]
            endPoint Solid {
              translation 0 0 0.125
              rotation 0 1 0 1.57
              children [
                HingeJoint {
                  device [
                    PositionSensor {
                    }
                    RotationalMotor {
                      name "R2"
                    }
                  ]
                  endPoint Solid {
                    children [
                      HingeJoint {
                        device [
                          PositionSensor {
                          }
                          RotationalMotor {
                            name "R3"
                          }
                        ]
                        endPoint Solid {
                          translation 0 0 0.5
                          children [
                            Shape {
                              appearance Appearance {
                                material Material {
                                  diffuseColor 1 0.666667 0
                                }
                              }
                              geometry Sphere {
                                radius 0.1
                              }
                            }
                          ]
                          name "Yellow"
                        }
                      }
                      Shape {
                        appearance Appearance {
                          material Material {
                            diffuseColor 0.666667 0 1
                          }
                        }
                        geometry Cylinder {
                          height 1
                          radius 0.01
                        }
                      }
                    ]
                    name "Purple"
                  }
                }
                Shape {
                  appearance Appearance {
                    material Material {
                      diffuseColor 0 0 0.498039
                    }
                  }
                  geometry Cylinder {
                    height 0.5
                    radius 0.05
                  }
                }
              ]
              name "Blue"
            }
          }
          Shape {
            geometry Cylinder {
              height 0.25
              radius 0.05
            }
          }
        ]
        name "White"
      }
    }
    Shape {
      appearance Appearance {
        material Material {
          diffuseColor 0.333333 1 0.498039
        }
      }
      geometry Cylinder {
        height 0.01
        radius 0.25
      }
    }
  ]
  name "Base"
}
