#VRML_SIM R2022a utf8
WorldInfo {
}
Viewpoint {
  orientation -0.22755624357101367 0.5690749563511454 0.7901720382712814 0.9369719843116974
  position -1.7939808462655291 -2.514036449082993 1.938078215485661
}
TexturedBackground {
}
TexturedBackgroundLight {
}
RectangleArena {
}
Robot {
  translation 0 0 0.025
  children [
    HingeJoint {
      jointParameters HingeJointParameters {
      }
      device [
        PositionSensor {
        }
        RotationalMotor {
          name "R1"
        }
      ]
      endPoint Solid {
        translation 0 0 0.125
        children [
          Solid {
            translation 0 0 0.125
            rotation 0 1 0 1.57
            children [
              SliderJoint {
                device [
                  LinearMotor {
                    name "L1"
                  }
                ]
                endPoint Solid {
                  translation 0 0 0.2
                  children [
                    HingeJoint {
                      device [
                        RotationalMotor {
                          name "R2"
                        }
                      ]
                      endPoint Solid {
                        translation 0 0 0.5
                        children [
                          Shape {
                            appearance Appearance {
                              material Material {
                                diffuseColor 0 0 0
                              }
                            }
                            geometry Sphere {
                              radius 0.1
                            }
                          }
                        ]
                        name "Black"
                      }
                    }
                    Shape {
                      appearance Appearance {
                        material Material {
                          diffuseColor 0.8 0.0235294 0.0392157
                        }
                      }
                      geometry Cylinder {
                        height 0.8
                        radius 0.02
                      }
                    }
                  ]
                  name "Red"
                }
              }
              Shape {
                appearance Appearance {
                  material Material {
                    diffuseColor 0 0.105882 0.8
                  }
                }
                geometry Cylinder {
                  height 0.5
                  radius 0.05
                }
              }
            ]
            name "Blue"
          }
          Shape {
            appearance Appearance {
              material Material {
                diffuseColor 0.694118 0.8 0.223529
              }
            }
            geometry Cylinder {
              height 0.25
              radius 0.05
            }
          }
        ]
        name "Green"
      }
    }
    Shape {
      appearance Appearance {
        material Material {
          diffuseColor 0.603922 0.505882 0.8
        }
      }
      geometry Cylinder {
        height 0.05
        radius 0.25
      }
    }
  ]
  name "Base"
  controllerArgs [
    ""
  ]
}
